[2024-10-31T23:59:54.056-0300] {local_task_job_runner.py:123} INFO - ::group::Pre task execution logs
[2024-10-31T23:59:54.107-0300] {taskinstance.py:2612} INFO - Dependencies all met for dep_context=non-requeueable deps ti=<TaskInstance: etl_redshift_dag_variables_fed.transform_data_fed_task scheduled__2024-10-30T19:00:00+00:00 [queued]>
[2024-10-31T23:59:54.148-0300] {taskinstance.py:2612} INFO - Dependencies all met for dep_context=requeueable deps ti=<TaskInstance: etl_redshift_dag_variables_fed.transform_data_fed_task scheduled__2024-10-30T19:00:00+00:00 [queued]>
[2024-10-31T23:59:54.154-0300] {taskinstance.py:2865} INFO - Starting attempt 4 of 4
[2024-10-31T23:59:54.282-0300] {taskinstance.py:2888} INFO - Executing <Task(PythonOperator): transform_data_fed_task> on 2024-10-30 19:00:00+00:00
[2024-10-31T23:59:54.305-0300] {standard_task_runner.py:72} INFO - Started process 153574 to run task
[2024-10-31T23:59:54.325-0300] {standard_task_runner.py:104} INFO - Running: ['airflow', 'tasks', 'run', 'etl_redshift_dag_variables_fed', 'transform_data_fed_task', 'scheduled__2024-10-30T19:00:00+00:00', '--job-id', '366', '--raw', '--subdir', 'DAGS_FOLDER/dag_variables_fed.py', '--cfg-path', '/tmp/tmp8w3dvxor']
[2024-10-31T23:59:54.331-0300] {standard_task_runner.py:105} INFO - Job 366: Subtask transform_data_fed_task
[2024-10-31T23:59:55.216-0300] {task_command.py:467} INFO - Running <TaskInstance: etl_redshift_dag_variables_fed.transform_data_fed_task scheduled__2024-10-30T19:00:00+00:00 [running]> on host DESKTOP-MVFODGC.
[2024-10-31T23:59:55.679-0300] {taskinstance.py:3131} INFO - Exporting env vars: AIRFLOW_CTX_DAG_OWNER='airflow' AIRFLOW_CTX_DAG_ID='etl_redshift_dag_variables_fed' AIRFLOW_CTX_TASK_ID='transform_data_fed_task' AIRFLOW_CTX_EXECUTION_DATE='2024-10-30T19:00:00+00:00' AIRFLOW_CTX_TRY_NUMBER='4' AIRFLOW_CTX_DAG_RUN_ID='scheduled__2024-10-30T19:00:00+00:00'
[2024-10-31T23:59:55.689-0300] {logging_mixin.py:190} INFO - Task instance is in running state
[2024-10-31T23:59:55.693-0300] {logging_mixin.py:190} INFO -  Previous state of the Task instance: queued
[2024-10-31T23:59:55.697-0300] {logging_mixin.py:190} INFO - Current task name:transform_data_fed_task state:running start_date:2024-11-01 02:59:54.110418+00:00
[2024-10-31T23:59:55.704-0300] {logging_mixin.py:190} INFO - Dag name:etl_redshift_dag_variables_fed and current dag run status:running
[2024-10-31T23:59:55.710-0300] {taskinstance.py:731} INFO - ::endgroup::
[2024-10-31T23:59:55.755-0300] {taskinstance.py:3310} ERROR - Task failed with exception
Traceback (most recent call last):
  File "/home/nico/.local/lib/python3.10/site-packages/airflow/models/taskinstance.py", line 767, in _execute_task
    result = _execute_callable(context=context, **execute_callable_kwargs)
  File "/home/nico/.local/lib/python3.10/site-packages/airflow/models/taskinstance.py", line 733, in _execute_callable
    return ExecutionCallableRunner(
  File "/home/nico/.local/lib/python3.10/site-packages/airflow/utils/operator_helpers.py", line 252, in run
    return self.func(*args, **kwargs)
  File "/home/nico/.local/lib/python3.10/site-packages/airflow/models/baseoperator.py", line 406, in wrapper
    return func(self, *args, **kwargs)
  File "/home/nico/.local/lib/python3.10/site-packages/airflow/operators/python.py", line 238, in execute
    return_value = self.execute_callable()
  File "/home/nico/.local/lib/python3.10/site-packages/airflow/operators/python.py", line 256, in execute_callable
    return runner.run(*self.op_args, **self.op_kwargs)
  File "/home/nico/.local/lib/python3.10/site-packages/airflow/utils/operator_helpers.py", line 252, in run
    return self.func(*args, **kwargs)
  File "/mnt/c/Users/Nicolas/OneDrive - BCRA/Cursos/Python Data Application (ITBA)/variables-economicas/dags/../scripts/transform_data_fed.py", line 21, in transform_data_fed
    raise ValueError("No se encontró data en XCom para 'extracted_data'")
ValueError: No se encontró data en XCom para 'extracted_data'
[2024-10-31T23:59:55.820-0300] {logging_mixin.py:190} INFO - Task instance in failure state
[2024-10-31T23:59:55.828-0300] {logging_mixin.py:190} INFO - Task start:2024-11-01 02:59:54.110418+00:00 end:2024-11-01 02:59:55.818584+00:00 duration:1.708166
[2024-10-31T23:59:55.832-0300] {logging_mixin.py:190} INFO - Task:<Task(PythonOperator): transform_data_fed_task> dag:<DAG: etl_redshift_dag_variables_fed> dagrun:<DagRun etl_redshift_dag_variables_fed @ 2024-10-30 19:00:00+00:00: scheduled__2024-10-30T19:00:00+00:00, state:running, queued_at: 2024-11-01 02:54:36.861830+00:00. externally triggered: False>
[2024-10-31T23:59:55.838-0300] {logging_mixin.py:190} INFO - Failure caused by No se encontró data en XCom para 'extracted_data'
[2024-10-31T23:59:55.841-0300] {taskinstance.py:1225} INFO - Marking task as FAILED. dag_id=etl_redshift_dag_variables_fed, task_id=transform_data_fed_task, run_id=scheduled__2024-10-30T19:00:00+00:00, execution_date=20241030T190000, start_date=20241101T025954, end_date=20241101T025955
[2024-10-31T23:59:55.952-0300] {taskinstance.py:340} INFO - ::group::Post task execution logs
[2024-10-31T23:59:55.955-0300] {standard_task_runner.py:124} ERROR - Failed to execute job 366 for task transform_data_fed_task (No se encontró data en XCom para 'extracted_data'; 153574)
Traceback (most recent call last):
  File "/home/nico/.local/lib/python3.10/site-packages/airflow/task/task_runner/standard_task_runner.py", line 117, in _start_by_fork
    ret = args.func(args, dag=self.dag)
  File "/home/nico/.local/lib/python3.10/site-packages/airflow/cli/cli_config.py", line 49, in command
    return func(*args, **kwargs)
  File "/home/nico/.local/lib/python3.10/site-packages/airflow/utils/cli.py", line 115, in wrapper
    return f(*args, **kwargs)
  File "/home/nico/.local/lib/python3.10/site-packages/airflow/cli/commands/task_command.py", line 483, in task_run
    task_return_code = _run_task_by_selected_method(args, _dag, ti)
  File "/home/nico/.local/lib/python3.10/site-packages/airflow/cli/commands/task_command.py", line 256, in _run_task_by_selected_method
    return _run_raw_task(args, ti)
  File "/home/nico/.local/lib/python3.10/site-packages/airflow/cli/commands/task_command.py", line 341, in _run_raw_task
    return ti._run_raw_task(
  File "/home/nico/.local/lib/python3.10/site-packages/airflow/utils/session.py", line 97, in wrapper
    return func(*args, session=session, **kwargs)
  File "/home/nico/.local/lib/python3.10/site-packages/airflow/models/taskinstance.py", line 3004, in _run_raw_task
    return _run_raw_task(
  File "/home/nico/.local/lib/python3.10/site-packages/airflow/models/taskinstance.py", line 273, in _run_raw_task
    TaskInstance._execute_task_with_callbacks(
  File "/home/nico/.local/lib/python3.10/site-packages/airflow/models/taskinstance.py", line 3158, in _execute_task_with_callbacks
    result = self._execute_task(context, task_orig)
  File "/home/nico/.local/lib/python3.10/site-packages/airflow/models/taskinstance.py", line 3182, in _execute_task
    return _execute_task(self, context, task_orig)
  File "/home/nico/.local/lib/python3.10/site-packages/airflow/models/taskinstance.py", line 767, in _execute_task
    result = _execute_callable(context=context, **execute_callable_kwargs)
  File "/home/nico/.local/lib/python3.10/site-packages/airflow/models/taskinstance.py", line 733, in _execute_callable
    return ExecutionCallableRunner(
  File "/home/nico/.local/lib/python3.10/site-packages/airflow/utils/operator_helpers.py", line 252, in run
    return self.func(*args, **kwargs)
  File "/home/nico/.local/lib/python3.10/site-packages/airflow/models/baseoperator.py", line 406, in wrapper
    return func(self, *args, **kwargs)
  File "/home/nico/.local/lib/python3.10/site-packages/airflow/operators/python.py", line 238, in execute
    return_value = self.execute_callable()
  File "/home/nico/.local/lib/python3.10/site-packages/airflow/operators/python.py", line 256, in execute_callable
    return runner.run(*self.op_args, **self.op_kwargs)
  File "/home/nico/.local/lib/python3.10/site-packages/airflow/utils/operator_helpers.py", line 252, in run
    return self.func(*args, **kwargs)
  File "/mnt/c/Users/Nicolas/OneDrive - BCRA/Cursos/Python Data Application (ITBA)/variables-economicas/dags/../scripts/transform_data_fed.py", line 21, in transform_data_fed
    raise ValueError("No se encontró data en XCom para 'extracted_data'")
ValueError: No se encontró data en XCom para 'extracted_data'
[2024-10-31T23:59:55.994-0300] {local_task_job_runner.py:266} INFO - Task exited with return code 1
[2024-10-31T23:59:56.109-0300] {taskinstance.py:3900} INFO - 0 downstream tasks scheduled from follow-on schedule check
[2024-10-31T23:59:56.174-0300] {local_task_job_runner.py:245} INFO - ::endgroup::
