[2024-10-31T23:59:18.492-0300] {local_task_job_runner.py:123} INFO - ::group::Pre task execution logs
[2024-10-31T23:59:18.551-0300] {taskinstance.py:2612} INFO - Dependencies all met for dep_context=non-requeueable deps ti=<TaskInstance: etl_redshift_dag_variables_fed.transform_data_fed_task manual__2024-11-01T02:55:54.147174+00:00 [queued]>
[2024-10-31T23:59:18.602-0300] {taskinstance.py:2612} INFO - Dependencies all met for dep_context=requeueable deps ti=<TaskInstance: etl_redshift_dag_variables_fed.transform_data_fed_task manual__2024-11-01T02:55:54.147174+00:00 [queued]>
[2024-10-31T23:59:18.606-0300] {taskinstance.py:2865} INFO - Starting attempt 1 of 2
[2024-10-31T23:59:18.713-0300] {taskinstance.py:2888} INFO - Executing <Task(PythonOperator): transform_data_fed_task> on 2024-11-01 02:55:54.147174+00:00
[2024-10-31T23:59:18.730-0300] {standard_task_runner.py:72} INFO - Started process 153419 to run task
[2024-10-31T23:59:18.745-0300] {standard_task_runner.py:104} INFO - Running: ['airflow', 'tasks', 'run', 'etl_redshift_dag_variables_fed', 'transform_data_fed_task', 'manual__2024-11-01T02:55:54.147174+00:00', '--job-id', '365', '--raw', '--subdir', 'DAGS_FOLDER/dag_variables_fed.py', '--cfg-path', '/tmp/tmp77a0fvin']
[2024-10-31T23:59:18.749-0300] {standard_task_runner.py:105} INFO - Job 365: Subtask transform_data_fed_task
[2024-10-31T23:59:19.009-0300] {task_command.py:467} INFO - Running <TaskInstance: etl_redshift_dag_variables_fed.transform_data_fed_task manual__2024-11-01T02:55:54.147174+00:00 [running]> on host DESKTOP-MVFODGC.
[2024-10-31T23:59:20.034-0300] {taskinstance.py:3131} INFO - Exporting env vars: AIRFLOW_CTX_DAG_OWNER='airflow' AIRFLOW_CTX_DAG_ID='etl_redshift_dag_variables_fed' AIRFLOW_CTX_TASK_ID='transform_data_fed_task' AIRFLOW_CTX_EXECUTION_DATE='2024-11-01T02:55:54.147174+00:00' AIRFLOW_CTX_TRY_NUMBER='1' AIRFLOW_CTX_DAG_RUN_ID='manual__2024-11-01T02:55:54.147174+00:00'
[2024-10-31T23:59:20.043-0300] {logging_mixin.py:190} INFO - Task instance is in running state
[2024-10-31T23:59:20.049-0300] {logging_mixin.py:190} INFO -  Previous state of the Task instance: queued
[2024-10-31T23:59:20.069-0300] {logging_mixin.py:190} INFO - Current task name:transform_data_fed_task state:running start_date:2024-11-01 02:59:18.562924+00:00
[2024-10-31T23:59:20.074-0300] {logging_mixin.py:190} INFO - Dag name:etl_redshift_dag_variables_fed and current dag run status:running
[2024-10-31T23:59:20.077-0300] {taskinstance.py:731} INFO - ::endgroup::
[2024-10-31T23:59:20.152-0300] {taskinstance.py:3310} ERROR - Task failed with exception
Traceback (most recent call last):
  File "/home/nico/.local/lib/python3.10/site-packages/airflow/models/taskinstance.py", line 767, in _execute_task
    result = _execute_callable(context=context, **execute_callable_kwargs)
  File "/home/nico/.local/lib/python3.10/site-packages/airflow/models/taskinstance.py", line 733, in _execute_callable
    return ExecutionCallableRunner(
  File "/home/nico/.local/lib/python3.10/site-packages/airflow/utils/operator_helpers.py", line 252, in run
    return self.func(*args, **kwargs)
  File "/home/nico/.local/lib/python3.10/site-packages/airflow/models/baseoperator.py", line 406, in wrapper
    return func(self, *args, **kwargs)
  File "/home/nico/.local/lib/python3.10/site-packages/airflow/operators/python.py", line 238, in execute
    return_value = self.execute_callable()
  File "/home/nico/.local/lib/python3.10/site-packages/airflow/operators/python.py", line 256, in execute_callable
    return runner.run(*self.op_args, **self.op_kwargs)
  File "/home/nico/.local/lib/python3.10/site-packages/airflow/utils/operator_helpers.py", line 252, in run
    return self.func(*args, **kwargs)
  File "/mnt/c/Users/Nicolas/OneDrive - BCRA/Cursos/Python Data Application (ITBA)/variables-economicas/dags/../scripts/transform_data_fed.py", line 21, in transform_data_fed
    raise ValueError("No se encontró data en XCom para 'extracted_data'")
ValueError: No se encontró data en XCom para 'extracted_data'
[2024-10-31T23:59:20.298-0300] {logging_mixin.py:190} INFO - Task instance in failure state
[2024-10-31T23:59:20.308-0300] {logging_mixin.py:190} INFO - Task start:2024-11-01 02:59:18.562924+00:00 end:2024-11-01 02:59:20.297168+00:00 duration:1.734244
[2024-10-31T23:59:20.317-0300] {logging_mixin.py:190} INFO - Task:<Task(PythonOperator): transform_data_fed_task> dag:<DAG: etl_redshift_dag_variables_fed> dagrun:<DagRun etl_redshift_dag_variables_fed @ 2024-11-01 02:55:54.147174+00:00: manual__2024-11-01T02:55:54.147174+00:00, state:running, queued_at: 2024-11-01 02:55:55.288721+00:00. externally triggered: True>
[2024-10-31T23:59:20.325-0300] {logging_mixin.py:190} INFO - Failure caused by No se encontró data en XCom para 'extracted_data'
[2024-10-31T23:59:20.333-0300] {taskinstance.py:1225} INFO - Marking task as UP_FOR_RETRY. dag_id=etl_redshift_dag_variables_fed, task_id=transform_data_fed_task, run_id=manual__2024-11-01T02:55:54.147174+00:00, execution_date=20241101T025554, start_date=20241101T025918, end_date=20241101T025920
[2024-10-31T23:59:21.244-0300] {taskinstance.py:340} INFO - ::group::Post task execution logs
[2024-10-31T23:59:21.274-0300] {standard_task_runner.py:124} ERROR - Failed to execute job 365 for task transform_data_fed_task (No se encontró data en XCom para 'extracted_data'; 153419)
Traceback (most recent call last):
  File "/home/nico/.local/lib/python3.10/site-packages/airflow/task/task_runner/standard_task_runner.py", line 117, in _start_by_fork
    ret = args.func(args, dag=self.dag)
  File "/home/nico/.local/lib/python3.10/site-packages/airflow/cli/cli_config.py", line 49, in command
    return func(*args, **kwargs)
  File "/home/nico/.local/lib/python3.10/site-packages/airflow/utils/cli.py", line 115, in wrapper
    return f(*args, **kwargs)
  File "/home/nico/.local/lib/python3.10/site-packages/airflow/cli/commands/task_command.py", line 483, in task_run
    task_return_code = _run_task_by_selected_method(args, _dag, ti)
  File "/home/nico/.local/lib/python3.10/site-packages/airflow/cli/commands/task_command.py", line 256, in _run_task_by_selected_method
    return _run_raw_task(args, ti)
  File "/home/nico/.local/lib/python3.10/site-packages/airflow/cli/commands/task_command.py", line 341, in _run_raw_task
    return ti._run_raw_task(
  File "/home/nico/.local/lib/python3.10/site-packages/airflow/utils/session.py", line 97, in wrapper
    return func(*args, session=session, **kwargs)
  File "/home/nico/.local/lib/python3.10/site-packages/airflow/models/taskinstance.py", line 3004, in _run_raw_task
    return _run_raw_task(
  File "/home/nico/.local/lib/python3.10/site-packages/airflow/models/taskinstance.py", line 273, in _run_raw_task
    TaskInstance._execute_task_with_callbacks(
  File "/home/nico/.local/lib/python3.10/site-packages/airflow/models/taskinstance.py", line 3158, in _execute_task_with_callbacks
    result = self._execute_task(context, task_orig)
  File "/home/nico/.local/lib/python3.10/site-packages/airflow/models/taskinstance.py", line 3182, in _execute_task
    return _execute_task(self, context, task_orig)
  File "/home/nico/.local/lib/python3.10/site-packages/airflow/models/taskinstance.py", line 767, in _execute_task
    result = _execute_callable(context=context, **execute_callable_kwargs)
  File "/home/nico/.local/lib/python3.10/site-packages/airflow/models/taskinstance.py", line 733, in _execute_callable
    return ExecutionCallableRunner(
  File "/home/nico/.local/lib/python3.10/site-packages/airflow/utils/operator_helpers.py", line 252, in run
    return self.func(*args, **kwargs)
  File "/home/nico/.local/lib/python3.10/site-packages/airflow/models/baseoperator.py", line 406, in wrapper
    return func(self, *args, **kwargs)
  File "/home/nico/.local/lib/python3.10/site-packages/airflow/operators/python.py", line 238, in execute
    return_value = self.execute_callable()
  File "/home/nico/.local/lib/python3.10/site-packages/airflow/operators/python.py", line 256, in execute_callable
    return runner.run(*self.op_args, **self.op_kwargs)
  File "/home/nico/.local/lib/python3.10/site-packages/airflow/utils/operator_helpers.py", line 252, in run
    return self.func(*args, **kwargs)
  File "/mnt/c/Users/Nicolas/OneDrive - BCRA/Cursos/Python Data Application (ITBA)/variables-economicas/dags/../scripts/transform_data_fed.py", line 21, in transform_data_fed
    raise ValueError("No se encontró data en XCom para 'extracted_data'")
ValueError: No se encontró data en XCom para 'extracted_data'
[2024-10-31T23:59:21.497-0300] {local_task_job_runner.py:266} INFO - Task exited with return code 1
[2024-10-31T23:59:22.610-0300] {taskinstance.py:3900} INFO - 0 downstream tasks scheduled from follow-on schedule check
[2024-10-31T23:59:22.659-0300] {local_task_job_runner.py:245} INFO - ::endgroup::
