[2024-11-02T23:00:16.957-0300] {local_task_job_runner.py:123} INFO - ::group::Pre task execution logs
[2024-11-02T23:00:17.015-0300] {taskinstance.py:2612} INFO - Dependencies all met for dep_context=non-requeueable deps ti=<TaskInstance: etl_redshift_dag_variables_fed.load_to_redshift_task scheduled__2024-11-01T22:00:00+00:00 [queued]>
[2024-11-02T23:00:17.055-0300] {taskinstance.py:2612} INFO - Dependencies all met for dep_context=requeueable deps ti=<TaskInstance: etl_redshift_dag_variables_fed.load_to_redshift_task scheduled__2024-11-01T22:00:00+00:00 [queued]>
[2024-11-02T23:00:17.057-0300] {taskinstance.py:2865} INFO - Starting attempt 2 of 3
[2024-11-02T23:00:17.161-0300] {taskinstance.py:2888} INFO - Executing <Task(PythonOperator): load_to_redshift_task> on 2024-11-01 22:00:00+00:00
[2024-11-02T23:00:17.179-0300] {standard_task_runner.py:72} INFO - Started process 221189 to run task
[2024-11-02T23:00:17.200-0300] {standard_task_runner.py:104} INFO - Running: ['airflow', 'tasks', 'run', 'etl_redshift_dag_variables_fed', 'load_to_redshift_task', 'scheduled__2024-11-01T22:00:00+00:00', '--job-id', '573', '--raw', '--subdir', 'DAGS_FOLDER/dag_variables_fed.py', '--cfg-path', '/tmp/tmpwqs6n792']
[2024-11-02T23:00:17.211-0300] {standard_task_runner.py:105} INFO - Job 573: Subtask load_to_redshift_task
[2024-11-02T23:00:17.483-0300] {task_command.py:467} INFO - Running <TaskInstance: etl_redshift_dag_variables_fed.load_to_redshift_task scheduled__2024-11-01T22:00:00+00:00 [running]> on host DESKTOP-MVFODGC.
[2024-11-02T23:00:17.800-0300] {taskinstance.py:3131} INFO - Exporting env vars: AIRFLOW_CTX_DAG_OWNER='airflow' AIRFLOW_CTX_DAG_ID='etl_redshift_dag_variables_fed' AIRFLOW_CTX_TASK_ID='load_to_redshift_task' AIRFLOW_CTX_EXECUTION_DATE='2024-11-01T22:00:00+00:00' AIRFLOW_CTX_TRY_NUMBER='2' AIRFLOW_CTX_DAG_RUN_ID='scheduled__2024-11-01T22:00:00+00:00'
[2024-11-02T23:00:17.803-0300] {logging_mixin.py:190} INFO - Task instance is in running state
[2024-11-02T23:00:17.807-0300] {logging_mixin.py:190} INFO -  Previous state of the Task instance: queued
[2024-11-02T23:00:17.814-0300] {logging_mixin.py:190} INFO - Current task name:load_to_redshift_task state:running start_date:2024-11-03 02:00:17.018549+00:00
[2024-11-02T23:00:17.819-0300] {logging_mixin.py:190} INFO - Dag name:etl_redshift_dag_variables_fed and current dag run status:running
[2024-11-02T23:00:17.823-0300] {taskinstance.py:731} INFO - ::endgroup::
[2024-11-02T23:00:31.864-0300] {_write.py:249} ERROR - {'S': 'ERROR', 'C': '22P02', 'M': 'invalid input syntax for type numeric: "."', 'F': '/home/ec2-user/padb/src/pg/src/backend/utils/adt/xennumeric_utils.c', 'L': '37', 'R': 'can_parse_number_error'}
[2024-11-02T23:00:31.875-0300] {taskinstance.py:3310} ERROR - Task failed with exception
Traceback (most recent call last):
  File "/mnt/c/Users/Nicolas/OneDrive - BCRA/Cursos/Python Data Application (ITBA)/variables-economicas/dags/../scripts/load_to_redshift_fed.py", line 47, in load_to_redshift_fed
    wr.redshift.to_sql(
  File "/home/nico/.local/lib/python3.10/site-packages/awswrangler/_utils.py", line 126, in inner
    return func(*args, **kwargs)
  File "/home/nico/.local/lib/python3.10/site-packages/awswrangler/_config.py", line 715, in wrapper
    return function(**args)
  File "/home/nico/.local/lib/python3.10/site-packages/awswrangler/redshift/_write.py", line 234, in to_sql
    cursor.executemany(sql, (parameters,))
  File "/home/nico/.local/lib/python3.10/site-packages/redshift_connector/cursor.py", line 272, in executemany
    self.execute(operation, parameters)
  File "/home/nico/.local/lib/python3.10/site-packages/redshift_connector/cursor.py", line 248, in execute
    raise e
  File "/home/nico/.local/lib/python3.10/site-packages/redshift_connector/cursor.py", line 241, in execute
    self._c.execute(self, operation, args)
  File "/home/nico/.local/lib/python3.10/site-packages/redshift_connector/core.py", line 1996, in execute
    self.handle_messages(cursor)
  File "/home/nico/.local/lib/python3.10/site-packages/redshift_connector/core.py", line 2203, in handle_messages
    raise self.error
redshift_connector.error.ProgrammingError: {'S': 'ERROR', 'C': '22P02', 'M': 'invalid input syntax for type numeric: "."', 'F': '/home/ec2-user/padb/src/pg/src/backend/utils/adt/xennumeric_utils.c', 'L': '37', 'R': 'can_parse_number_error'}

During handling of the above exception, another exception occurred:

Traceback (most recent call last):
  File "/home/nico/.local/lib/python3.10/site-packages/airflow/models/taskinstance.py", line 767, in _execute_task
    result = _execute_callable(context=context, **execute_callable_kwargs)
  File "/home/nico/.local/lib/python3.10/site-packages/airflow/models/taskinstance.py", line 733, in _execute_callable
    return ExecutionCallableRunner(
  File "/home/nico/.local/lib/python3.10/site-packages/airflow/utils/operator_helpers.py", line 252, in run
    return self.func(*args, **kwargs)
  File "/home/nico/.local/lib/python3.10/site-packages/airflow/models/baseoperator.py", line 406, in wrapper
    return func(self, *args, **kwargs)
  File "/home/nico/.local/lib/python3.10/site-packages/airflow/operators/python.py", line 238, in execute
    return_value = self.execute_callable()
  File "/home/nico/.local/lib/python3.10/site-packages/airflow/operators/python.py", line 256, in execute_callable
    return runner.run(*self.op_args, **self.op_kwargs)
  File "/home/nico/.local/lib/python3.10/site-packages/airflow/utils/operator_helpers.py", line 252, in run
    return self.func(*args, **kwargs)
  File "/mnt/c/Users/Nicolas/OneDrive - BCRA/Cursos/Python Data Application (ITBA)/variables-economicas/dags/../scripts/load_to_redshift_fed.py", line 61, in load_to_redshift_fed
    raise Exception(f"Error en la conexi贸n o carga de datos a Redshift: {e}")
Exception: Error en la conexi贸n o carga de datos a Redshift: {'S': 'ERROR', 'C': '22P02', 'M': 'invalid input syntax for type numeric: "."', 'F': '/home/ec2-user/padb/src/pg/src/backend/utils/adt/xennumeric_utils.c', 'L': '37', 'R': 'can_parse_number_error'}
[2024-11-02T23:00:31.970-0300] {logging_mixin.py:190} INFO - Task instance in failure state
[2024-11-02T23:00:31.973-0300] {logging_mixin.py:190} INFO - Task start:2024-11-03 02:00:17.018549+00:00 end:2024-11-03 02:00:31.970087+00:00 duration:14.951538
[2024-11-02T23:00:31.979-0300] {logging_mixin.py:190} INFO - Task:<Task(PythonOperator): load_to_redshift_task> dag:<DAG: etl_redshift_dag_variables_fed> dagrun:<DagRun etl_redshift_dag_variables_fed @ 2024-11-01 22:00:00+00:00: scheduled__2024-11-01T22:00:00+00:00, state:running, queued_at: 2024-11-03 01:57:51.015997+00:00. externally triggered: False>
[2024-11-02T23:00:31.982-0300] {logging_mixin.py:190} INFO - Failure caused by Error en la conexi贸n o carga de datos a Redshift: {'S': 'ERROR', 'C': '22P02', 'M': 'invalid input syntax for type numeric: "."', 'F': '/home/ec2-user/padb/src/pg/src/backend/utils/adt/xennumeric_utils.c', 'L': '37', 'R': 'can_parse_number_error'}
[2024-11-02T23:00:31.988-0300] {taskinstance.py:1225} INFO - Marking task as UP_FOR_RETRY. dag_id=etl_redshift_dag_variables_fed, task_id=load_to_redshift_task, run_id=scheduled__2024-11-01T22:00:00+00:00, execution_date=20241101T220000, start_date=20241103T020017, end_date=20241103T020031
[2024-11-02T23:00:32.115-0300] {taskinstance.py:340} INFO - ::group::Post task execution logs
[2024-11-02T23:00:32.118-0300] {standard_task_runner.py:124} ERROR - Failed to execute job 573 for task load_to_redshift_task (Error en la conexi贸n o carga de datos a Redshift: {'S': 'ERROR', 'C': '22P02', 'M': 'invalid input syntax for type numeric: "."', 'F': '/home/ec2-user/padb/src/pg/src/backend/utils/adt/xennumeric_utils.c', 'L': '37', 'R': 'can_parse_number_error'}; 221189)
Traceback (most recent call last):
  File "/mnt/c/Users/Nicolas/OneDrive - BCRA/Cursos/Python Data Application (ITBA)/variables-economicas/dags/../scripts/load_to_redshift_fed.py", line 47, in load_to_redshift_fed
    wr.redshift.to_sql(
  File "/home/nico/.local/lib/python3.10/site-packages/awswrangler/_utils.py", line 126, in inner
    return func(*args, **kwargs)
  File "/home/nico/.local/lib/python3.10/site-packages/awswrangler/_config.py", line 715, in wrapper
    return function(**args)
  File "/home/nico/.local/lib/python3.10/site-packages/awswrangler/redshift/_write.py", line 234, in to_sql
    cursor.executemany(sql, (parameters,))
  File "/home/nico/.local/lib/python3.10/site-packages/redshift_connector/cursor.py", line 272, in executemany
    self.execute(operation, parameters)
  File "/home/nico/.local/lib/python3.10/site-packages/redshift_connector/cursor.py", line 248, in execute
    raise e
  File "/home/nico/.local/lib/python3.10/site-packages/redshift_connector/cursor.py", line 241, in execute
    self._c.execute(self, operation, args)
  File "/home/nico/.local/lib/python3.10/site-packages/redshift_connector/core.py", line 1996, in execute
    self.handle_messages(cursor)
  File "/home/nico/.local/lib/python3.10/site-packages/redshift_connector/core.py", line 2203, in handle_messages
    raise self.error
redshift_connector.error.ProgrammingError: {'S': 'ERROR', 'C': '22P02', 'M': 'invalid input syntax for type numeric: "."', 'F': '/home/ec2-user/padb/src/pg/src/backend/utils/adt/xennumeric_utils.c', 'L': '37', 'R': 'can_parse_number_error'}

During handling of the above exception, another exception occurred:

Traceback (most recent call last):
  File "/home/nico/.local/lib/python3.10/site-packages/airflow/task/task_runner/standard_task_runner.py", line 117, in _start_by_fork
    ret = args.func(args, dag=self.dag)
  File "/home/nico/.local/lib/python3.10/site-packages/airflow/cli/cli_config.py", line 49, in command
    return func(*args, **kwargs)
  File "/home/nico/.local/lib/python3.10/site-packages/airflow/utils/cli.py", line 115, in wrapper
    return f(*args, **kwargs)
  File "/home/nico/.local/lib/python3.10/site-packages/airflow/cli/commands/task_command.py", line 483, in task_run
    task_return_code = _run_task_by_selected_method(args, _dag, ti)
  File "/home/nico/.local/lib/python3.10/site-packages/airflow/cli/commands/task_command.py", line 256, in _run_task_by_selected_method
    return _run_raw_task(args, ti)
  File "/home/nico/.local/lib/python3.10/site-packages/airflow/cli/commands/task_command.py", line 341, in _run_raw_task
    return ti._run_raw_task(
  File "/home/nico/.local/lib/python3.10/site-packages/airflow/utils/session.py", line 97, in wrapper
    return func(*args, session=session, **kwargs)
  File "/home/nico/.local/lib/python3.10/site-packages/airflow/models/taskinstance.py", line 3004, in _run_raw_task
    return _run_raw_task(
  File "/home/nico/.local/lib/python3.10/site-packages/airflow/models/taskinstance.py", line 273, in _run_raw_task
    TaskInstance._execute_task_with_callbacks(
  File "/home/nico/.local/lib/python3.10/site-packages/airflow/models/taskinstance.py", line 3158, in _execute_task_with_callbacks
    result = self._execute_task(context, task_orig)
  File "/home/nico/.local/lib/python3.10/site-packages/airflow/models/taskinstance.py", line 3182, in _execute_task
    return _execute_task(self, context, task_orig)
  File "/home/nico/.local/lib/python3.10/site-packages/airflow/models/taskinstance.py", line 767, in _execute_task
    result = _execute_callable(context=context, **execute_callable_kwargs)
  File "/home/nico/.local/lib/python3.10/site-packages/airflow/models/taskinstance.py", line 733, in _execute_callable
    return ExecutionCallableRunner(
  File "/home/nico/.local/lib/python3.10/site-packages/airflow/utils/operator_helpers.py", line 252, in run
    return self.func(*args, **kwargs)
  File "/home/nico/.local/lib/python3.10/site-packages/airflow/models/baseoperator.py", line 406, in wrapper
    return func(self, *args, **kwargs)
  File "/home/nico/.local/lib/python3.10/site-packages/airflow/operators/python.py", line 238, in execute
    return_value = self.execute_callable()
  File "/home/nico/.local/lib/python3.10/site-packages/airflow/operators/python.py", line 256, in execute_callable
    return runner.run(*self.op_args, **self.op_kwargs)
  File "/home/nico/.local/lib/python3.10/site-packages/airflow/utils/operator_helpers.py", line 252, in run
    return self.func(*args, **kwargs)
  File "/mnt/c/Users/Nicolas/OneDrive - BCRA/Cursos/Python Data Application (ITBA)/variables-economicas/dags/../scripts/load_to_redshift_fed.py", line 61, in load_to_redshift_fed
    raise Exception(f"Error en la conexi贸n o carga de datos a Redshift: {e}")
Exception: Error en la conexi贸n o carga de datos a Redshift: {'S': 'ERROR', 'C': '22P02', 'M': 'invalid input syntax for type numeric: "."', 'F': '/home/ec2-user/padb/src/pg/src/backend/utils/adt/xennumeric_utils.c', 'L': '37', 'R': 'can_parse_number_error'}
[2024-11-02T23:00:32.181-0300] {local_task_job_runner.py:266} INFO - Task exited with return code 1
[2024-11-02T23:00:32.218-0300] {standard_task_runner.py:217} INFO - Process not found (most likely exited), stop collecting metrics
[2024-11-02T23:00:32.498-0300] {taskinstance.py:3900} INFO - 0 downstream tasks scheduled from follow-on schedule check
[2024-11-02T23:00:32.527-0300] {local_task_job_runner.py:245} INFO - ::endgroup::
